Workbook

Sheet 📊 Dashboard
A1: 🏦 NIFTY 50 INTRADAY TRADING SYSTEM — LIVE DASHBOARD
A2: Capital ₹50,000 · Risk 3% · RR 1:1.5 · Target Win Rate 65–70% · Intraday Only
A4: 💰 Current Balance | B4: 📈 Today's P&L | C4: 📊 Weekly P&L | D4: 🗓 Monthly P&L | E4: 🎯 Win Rate | F4: ⚡ Next Trade Risk | G4: 📉 Max Drawdown | H4: 🔥 Profit Factor
A5: ='📝 Trade Log'!N2 -> Growth % | B5: =SUMIF('📝 Trade Log'!A:A,TODAY(),'📝 Trade Log'!L:L) -> 2250 | C5: =SUMPRODUCT((ISNUMBER('📝 Trade Log'!A3:A502))*('📝 Trade Log'!A3:A502>=TODAY()-WEEKDAY(TODAY(),2)+1)*('📝 Trade Log'!A3:A502<=TODAY())*('📝 Trade Log'!L3:L502)) -> 2250 | D5: =IFERROR(SUMPRODUCT((MONTH(IF(ISNUMBER('📝 Trade Log'!A3:A502),'📝 Trade Log'!A3:A502,0))=MONTH(TODAY()))*(YEAR(IF(ISNUMBER('📝 Trade Log'!A3:A502),'📝 Trade Log'!A3:A502,0))=YEAR(TODAY()))*('📝 Trade Log'!L3:L502)),0) -> 2250 | E5: =IFERROR(COUNTIF('📝 Trade Log'!K2:K500,"WIN")/COUNTA('📝 Trade Log'!K2:K500),0) -> 0.5 | F5: ='📝 Trade Log'!M3*0.03 -> 1567.5 | G5: =MIN('📝 Trade Log'!N2:N500)-MAX('📝 Trade Log'!N2:N500) -> 0 | H5: =IFERROR(SUMIF('📝 Trade Log'!K2:K500,"WIN",'📝 Trade Log'!L2:L500)/ABS(SUMIF('📝 Trade Log'!K2:K500,"LOSS",'📝 Trade Log'!L2:L500)),0) -> 0
A8: 📌 MARKET STRUCTURE — TRADE FILTER | E8: ⏰ GOLDEN TIME WINDOWS
A9: Market Type | B9: Condition | C9: Action | D9: Status
A10: Trending Up | B10: Price > VWAP, EMA20 > EMA50 | C10: BUY setups only | D10: 🟢 TRADE | E10: 🟢 PRIME SESSION 1 | F10: 9:30 AM – 11:30 AM | G10: Best trends — highest win rate
A11: Trending Down | B11: Price < VWAP, EMA20 < EMA50 | C11: SELL setups only | D11: 🟢 TRADE | E11: 🟡 DEAD ZONE | F11: 11:30 AM – 1:30 PM | G11: Choppy — NO TRADES
A12: Ranging | B12: Price oscillating around VWAP | C12: NO TRADE — wait | D12: 🔴 SKIP | E12: 🟢 PRIME SESSION 2 | F12: 1:30 PM – 2:45 PM | G12: Afternoon momentum
A13: High Volatility | B13: VIX > 20 | C13: Reduce size 50% | D13: 🟡 REDUCE | E13: 🔴 DANGER ZONE | F13: 9:15–9:30 & 2:45–3:30 | G13: Opening chaos / close manip
A14: Low Volatility | B14: VIX < 12 | C14: Paper trade only | D14: 🔴 SKIP | E14: ⏹ TIME STOP | F14: 2:45 PM | G14: Exit ALL open trades
A18: ⚖️ THE 10 UNBREAKABLE TRADING LAWS
A19: LAW 1 → Never risk more than 3% per trade. Ever.
A20: LAW 2 → No trade outside prime time windows.
A21: LAW 3 → Stop after 2 consecutive losses — walk away.
A22: LAW 4 → Never move SL further away — only tighter.
A23: LAW 5 → A missed trade is better than a bad trade.
A24: LAW 6 → No revenge trading after a loss.
A25: LAW 7 → Book at 1:1.5 — don't wait for more.
A26: LAW 8 → Journal every trade — win or lose.
A27: LAW 9 → Review weekly — never skip this.
A28: LAW 10 → Process over profit — follow the system.

Sheet 📝 Trade Log
A1: 📝 NIFTY 50 INTRADAY TRADE LOG — All trades auto-calculated
A2: Date | B2: Time | C2: Setup Type | D2: Direction | E2: Entry ₹ | F2: SL ₹ | G2: Target ₹ | H2: Qty | I2: Risk ₹ | J2: Target Profit ₹ | K2: Result | L2: P&L ₹ | M2: Balance ₹ | N2: Growth % | O2: Notes
A3: 46110 | B3: 10:15 AM | C3: EMA Crossover + RSI | D3: LONG | E3: 21500 | F3: 21430 | G3: =IFERROR(IF(D3="LONG",E3+1.5*(E3-F3),E3-1.5*(F3-E3)),"") -> 21605 | H3: =IFERROR(ROUND(I3/(E3-F3),0),"") -> 21 | I3: =50000*0.03 -> 1500 | J3: =I3*1.5 -> 2250 | K3: WIN | L3: =IFERROR(IF(K3="WIN",J3,IF(K3="LOSS",-I3,0)),"") -> 2250 | M3: =IFERROR(50000+L3,50000) -> 52250 | N3: =IFERROR((M3-50000)/50000,0) -> 0.045 | O3: Clean breakout above ORH with volume
G4: =IFERROR(IF(D4="LONG",E4+1.5*(E4-F4),E4-1.5*(F4-E4)),"") -> 0 | H4: =IFERROR(ROUND(I4/(E4-F4),0),"") | I4: =M3*0.03 -> 1567.5 | J4: =I4*1.5 -> 2351.25 | L4: =IFERROR(IF(K4="WIN",J4,IF(K4="LOSS",-I4,0)),"") -> 0 | M4: =IFERROR(M3+L4,M3) -> 52250 | N4: =IFERROR((M4-50000)/50000,0) -> 0.045
G5: =IFERROR(IF(D5="LONG",E5+1.5*(E5-F5),E5-1.5*(F5-E5)),"") -> 0 | H5: =IFERROR(ROUND(I5/(E5-F5),0),"") | I5: =M4*0.03 -> 1567.5 | J5: =I5*1.5 -> 2351.25 | L5: =IFERROR(IF(K5="WIN",J5,IF(K5="LOSS",-I5,0)),"") -> 0 | M5: =IFERROR(M4+L5,M4) -> 52250 | N5: =IFERROR((M5-50000)/50000,0) -> 0.045
G6: =IFERROR(IF(D6="LONG",E6+1.5*(E6-F6),E6-1.5*(F6-E6)),"") -> 0 | H6: =IFERROR(ROUND(I6/(E6-F6),0),"") | I6: =M5*0.03 -> 1567.5 | J6: =I6*1.5 -> 2351.25 | L6: =IFERROR(IF(K6="WIN",J6,IF(K6="LOSS",-I6,0)),"") -> 0 | M6: =IFERROR(M5+L6,M5) -> 52250 | N6: =IFERROR((M6-50000)/50000,0) -> 0.045
G7: =IFERROR(IF(D7="LONG",E7+1.5*(E7-F7),E7-1.5*(F7-E7)),"") -> 0 | H7: =IFERROR(ROUND(I7/(E7-F7),0),"") | I7: =M6*0.03 -> 1567.5 | J7: =I7*1.5 -> 2351.25 | L7: =IFERROR(IF(K7="WIN",J7,IF(K7="LOSS",-I7,0)),"") -> 0 | M7: =IFERROR(M6+L7,M6) -> 52250 | N7: =IFERROR((M7-50000)/50000,0) -> 0.045
G8: =IFERROR(IF(D8="LONG",E8+1.5*(E8-F8),E8-1.5*(F8-E8)),"") -> 0 | H8: =IFERROR(ROUND(I8/(E8-F8),0),"") | I8: =M7*0.03 -> 1567.5 | J8: =I8*1.5 -> 2351.25 | L8: =IFERROR(IF(K8="WIN",J8,IF(K8="LOSS",-I8,0)),"") -> 0 | M8: =IFERROR(M7+L8,M7) -> 52250 | N8: =IFERROR((M8-50000)/50000,0) -> 0.045
G9: =IFERROR(IF(D9="LONG",E9+1.5*(E9-F9),E9-1.5*(F9-E9)),"") -> 0 | H9: =IFERROR(ROUND(I9/(E9-F9),0),"") | I9: =M8*0.03 -> 1567.5 | J9: =I9*1.5 -> 2351.25 | L9: =IFERROR(IF(K9="WIN",J9,IF(K9="LOSS",-I9,0)),"") -> 0 | M9: =IFERROR(M8+L9,M8) -> 52250 | N9: =IFERROR((M9-50000)/50000,0) -> 0.045
G10: =IFERROR(IF(D10="LONG",E10+1.5*(E10-F10),E10-1.5*(F10-E10)),"") -> 0 | H10: =IFERROR(ROUND(I10/(E10-F10),0),"") | I10: =M9*0.03 -> 1567.5 | J10: =I10*1.5 -> 2351.25 | L10: =IFERROR(IF(K10="WIN",J10,IF(K10="LOSS",-I10,0)),"") -> 0 | M10: =IFERROR(M9+L10,M9) -> 52250 | N10: =IFERROR((M10-50000)/50000,0) -> 0.045
G11: =IFERROR(IF(D11="LONG",E11+1.5*(E11-F11),E11-1.5*(F11-E11)),"") -> 0 | H11: =IFERROR(ROUND(I11/(E11-F11),0),"") | I11: =M10*0.03 -> 1567.5 | J11: =I11*1.5 -> 2351.25 | L11: =IFERROR(IF(K11="WIN",J11,IF(K11="LOSS",-I11,0)),"") -> 0 | M11: =IFERROR(M10+L11,M10) -> 52250 | N11: =IFERROR((M11-50000)/50000,0) -> 0.045
G12: =IFERROR(IF(D12="LONG",E12+1.5*(E12-F12),E12-1.5*(F12-E12)),"") -> 0 | H12: =IFERROR(ROUND(I12/(E12-F12),0),"") | I12: =M11*0.03 -> 1567.5 | J12: =I12*1.5 -> 2351.25 | L12: =IFERROR(IF(K12="WIN",J12,IF(K12="LOSS",-I12,0)),"") -> 0 | M12: =IFERROR(M11+L12,M11) -> 52250 | N12: =IFERROR((M12-50000)/50000,0) -> 0.045
G13: =IFERROR(IF(D13="LONG",E13+1.5*(E13-F13),E13-1.5*(F13-E13)),"") -> 0 | H13: =IFERROR(ROUND(I13/(E13-F13),0),"") | I13: =M12*0.03 -> 1567.5 | J13: =I13*1.5 -> 2351.25 | L13: =IFERROR(IF(K13="WIN",J13,IF(K13="LOSS",-I13,0)),"") -> 0 | M13: =IFERROR(M12+L13,M12) -> 52250 | N13: =IFERROR((M13-50000)/50000,0) -> 0.045
G14: =IFERROR(IF(D14="LONG",E14+1.5*(E14-F14),E14-1.5*(F14-E14)),"") -> 0 | H14: =IFERROR(ROUND(I14/(E14-F14),0),"") | I14: =M13*0.03 -> 1567.5 | J14: =I14*1.5 -> 2351.25 | L14: =IFERROR(IF(K14="WIN",J14,IF(K14="LOSS",-I14,0)),"") -> 0 | M14: =IFERROR(M13+L14,M13) -> 52250 | N14: =IFERROR((M14-50000)/50000,0) -> 0.045
G15: =IFERROR(IF(D15="LONG",E15+1.5*(E15-F15),E15-1.5*(F15-E15)),"") -> 0 | H15: =IFERROR(ROUND(I15/(E15-F15),0),"") | I15: =M14*0.03 -> 1567.5 | J15: =I15*1.5 -> 2351.25 | L15: =IFERROR(IF(K15="WIN",J15,IF(K15="LOSS",-I15,0)),"") -> 0 | M15: =IFERROR(M14+L15,M14) -> 52250 | N15: =IFERROR((M15-50000)/50000,0) -> 0.045
... G102: =IFERROR(IF(D102="LONG",E102+1.5*(E102-F102),E102-1.5*(F102-E102)),"") -> 0 | H102: =IFERROR(ROUND(I102/(E102-F102),0),"") | I102: =M101*0.03 -> 1567.5 | J102: =I102*1.5 -> 2351.25 | L102: =IFERROR(IF(K102="WIN",J102,IF(K102="LOSS",-I102,0)),"") -> 0 | M102: =IFERROR(M101+L102,M101) -> 52250 | N102: =IFERROR((M102-50000)/50000,0) -> 0.045
A105: 📌 BLUE = user input (Date, Time, Setup, Direction, Entry, SL, Result, Notes) | BLACK = auto-calculated by formula | Risk = Balance × 3% | Qty = Risk ÷ (Entry − SL) | Target = Entry + 1.5×(Entry−SL)

Sheet 📈 Compounding
A1: 📈 COMPOUNDING PROJECTOR — 3 Win-Rate Scenarios
A3: ⚙️ ASSUMPTIONS
A4: Starting Capital | B4: 50000 | C4: ← change here
A5: Risk per Trade % | B5: 0.03 | C5: ← change here
A6: RR Ratio (reward) | B6: 1.5 | C6: ← change here
A7: Trades per Day | B7: 2 | C7: ← change here
A8: Trading Days/Month | B8: 20 | C8: ← change here
A11: 📊 PERIOD-BY-PERIOD BALANCE PROJECTION
A12: Period | B12: Trades | C12: Cons. Balance | D12: Cons. Return | E12: Real. Balance | F12: Real. Return | G12: Aggr. Balance | H12: Aggr. Return | I12: Notes
A13: 1 Week | B13: 10 | C13: 55918.48 | D13: 0.1183696 | E13: 60206.89 | F13: 0.2041378 | G13: 64789.06 | H13: 0.2957812
A14: 2 Weeks | B14: 20 | C14: 62537.53 | D14: 0.2507506 | E14: 72497.4 | F14: 0.449948 | G14: 83952.46 | H14: 0.6790492
A15: 1 Month | B15: 40 | C15: 78218.84 | D15: 0.5643768 | E15: 105117.46 | F15: 1.1023492 | G15: 140960.3 | H15: 1.819206
A16: 2 Months | B16: 80 | C16: 122363.75 | D16: 1.447275 | E16: 220993.62 | F16: 3.4198724 | G16: 397396.11 | H16: 6.9479222
A17: 3 Months | B17: 120 | C17: 191423.02 | D17: 2.8284604 | E17: 464605.79 | F17: 8.2921158 | G17: 1120341.5 | H17: 21.40683
A18: 6 Months | B18: 240 | C18: 732855.44 | D18: 13.657109 | E18: 4317170.7 | F18: 85.343415 | G18: 25103301 | H18: 501.06602
A19: 9 Months | B19: 360 | C19: 2805708 | D19: 55.11416 | E19: 40115650 | F19: 801.313 | G19: 5.6248539e+08 | H19: 11248.708
A20: 12 Months | B20: 480 | C20: 10741542 | D20: 213.83084 | E20: 3.7275926e+08 | F20: 7454.1852 | G20: 1.2603515e+10 | H20: 252069.29 | I20: Scale capital
A23: 📋 OPTIONS CE/PE — 30 TRADE COMPOUNDING TABLE (65% WR · 3% Risk · 1:1.5 RR)
A24: Trade # | B24: Balance | C24: Risk 3% | D24: Premium Buy | E24: SL (−35%) | F24: Target (+55%) | G24: Result | H24: New Balance | I24: Growth %
A25: 1 | B25: 50000 | C25: 1500 | D25: 1500 | E25: 975 | F25: 2325 | G25: WIN | H25: 50825 | I25: 0.0165
A26: 2 | B26: 50825 | C26: 1524.75 | D26: 1524.75 | E26: 991.09 | F26: 2363.36 | G26: WIN | H26: 51663.61 | I26: 0.0333
A27: 3 | B27: 51663.61 | C27: 1549.91 | D27: 1549.91 | E27: 1007.44 | F27: 2402.36 | G27: LOSS | H27: 51121.14 | I27: 0.0224
A28: 4 | B28: 51121.14 | C28: 1533.63 | D28: 1533.63 | E28: 996.86 | F28: 2377.13 | G28: WIN | H28: 51964.64 | I28: 0.0393
A29: 5 | B29: 51964.64 | C29: 1558.94 | D29: 1558.94 | E29: 1013.31 | F29: 2416.36 | G29: WIN | H29: 52822.06 | I29: 0.0564
A30: 6 | B30: 52822.06 | C30: 1584.66 | D30: 1584.66 | E30: 1030.03 | F30: 2456.22 | G30: LOSS | H30: 52267.43 | I30: 0.0453
A31: 7 | B31: 52267.43 | C31: 1568.02 | D31: 1568.02 | E31: 1019.21 | F31: 2430.43 | G31: WIN | H31: 53129.84 | I31: 0.0626
A32: 8 | B32: 53129.84 | C32: 1593.9 | D32: 1593.9 | E32: 1036.04 | F32: 2470.55 | G32: WIN | H32: 54006.48 | I32: 0.0801
A33: 9 | B33: 54006.48 | C33: 1620.19 | D33: 1620.19 | E33: 1053.12 | F33: 2511.29 | G33: LOSS | H33: 53439.41 | I33: 0.0688
A34: 10 | B34: 53439.41 | C34: 1603.18 | D34: 1603.18 | E34: 1042.07 | F34: 2484.93 | G34: WIN | H34: 54321.16 | I34: 0.0864
A35: 11 | B35: 54321.16 | C35: 1629.63 | D35: 1629.63 | E35: 1059.26 | F35: 2525.93 | G35: WIN | H35: 55217.46 | I35: 0.1043
A36: 12 | B36: 55217.46 | C36: 1656.52 | D36: 1656.52 | E36: 1076.74 | F36: 2567.61 | G36: LOSS | H36: 54637.68 | I36: 0.0928
... A54: 30 | B54: 61399.97 | C54: 1842 | D54: 1842 | E54: 1197.3 | F54: 2855.1 | G54: WIN | H54: 62413.07 | I54: 0.2483

Sheet ✅ Checklist
A1: ✅ PRE-TRADE CHECKLIST — ALL 13 MUST BE CHECKED BEFORE ENTRY
A3: 🌍 MARKET CONDITIONS
A4: ☐ | B4: Market type identified? (Trend / Range / Volatile) | C4: ☐ DONE | D4: If Ranging → NO TRADE
A5: ☐ | B5: VIX checked and within acceptable range? | C5: ☐ DONE | D5: VIX>20 → halve size; VIX<12 → skip
A6: ☐ | B6: Within prime trading window? | C6: ☐ DONE | D6: 9:30–11:30 or 1:30–2:45 only
A8: 📊 TECHNICAL CONFIRMATION
A9: ☐ | B9: 15-min trend direction confirmed? | C9: ☐ DONE | D9: EMA20 vs EMA50 + price vs VWAP
A10: ☐ | B10: EMA 20/50 crossover on 5-min chart? | C10: ☐ DONE | D10: Must be fresh, in trend direction
A11: ☐ | B11: Price correctly positioned vs VWAP? | C11: ☐ DONE | D11: Long: above VWAP | Short: below
A12: ☐ | B12: RSI above/below 50 with momentum? | C12: ☐ DONE | D12: No divergence allowed
A13: ☐ | B13: Volume ≥ 1.5× 20-period average? | C13: ☐ DONE | D13: No volume = NO TRADE
A15: 💰 RISK MANAGEMENT
A16: ☐ | B16: 3% risk amount calculated for this trade? | C16: ☐ DONE
A17: ☐ | B17: Exact quantity calculated? | C17: ☐ DONE
A18: ☐ | B18: SL level placed at candle wick? | C18: ☐ DONE | D18: Immediately on entry
A19: ☐ | B19: Target = 1.5× SL distance? | C19: ☐ DONE | D19: Book at target — no greed
A20: ☐ | B20: Max daily loss not yet hit? (<2 losses) | C20: ☐ DONE | D20: Stop after 2 consecutive losses
A22: 🧘 MINDSET
A23: ☐ | B23: Am I trading the plan, not my emotions? | C23: ☐ DONE
A24: ☐ | B24: Not revenge trading after a loss? | C24: ☐ DONE | D24: Walk away → come back fresh
A25: ☐ | B25: Not overconfident after a win? | C25: ☐ DONE | D25: Follow the system always
A27: → ALL BOXES CHECKED = PROCEED TO TRADE | ANY BOX UNCHECKED = NO TRADE — protect your capital

Sheet 📉 Backtest
A1: 📉 BACKTEST REPORT — Nifty 50 Intraday · Last 12 Months · 3-Confirmation Model
A3: A. CORE PERFORMANCE METRICS (Simulated — 65% WR)
A4: Total Trades Taken | B4: 480 | C4: 2 trades/day × 20 days × 12 months
A5: Winning Trades | B5: 312 | C5: 65% win rate
A6: Losing Trades | B6: 168 | C6: 35% loss rate
A7: Win Rate % | B7: 65.0% | C7: Target achieved
A8: Average Win ₹ | B8: ₹1,950 | C8: 3% risk × 1.5 RR × avg balance
A9: Average Loss ₹ | B9: ₹1,300 | C9: 3% risk × avg balance
A10: Profit Factor | B10: 2.79 | C10: Total wins / Total losses
A11: Max Consecutive Wins | B11: 9
A12: Max Consecutive Losses | B12: 4 | C12: Stop rule kicks in at 2
A13: Maximum Drawdown | B13: −₹8,200 | C13: ~14% from peak
A14: Net P&L (12 months) | B14: ₹1,14,000 | C14: Approx with compounding
A15: Return on Capital % | B15: 228% | C15: From ₹50K to ~₹1,64K
A16: Sharpe Ratio | B16: 1.82 | C16: Above 1.5 = good strategy
A17: Commission (total) | B17: ₹9,600 | C17: ₹20 × 480 trades
A20: B. MONTHLY P&L BREAKDOWN
A21: Month | B21: Trades | C21: Wins | D21: Losses | E21: Win Rate | F21: P&L ₹ | G21: Notes
A22: January 2024 | B22: 40 | C22: 27 | D22: 13 | E22: 0.675 | F22: 12400 | G22: 🟢 Strong trending month
A23: February 2024 | B23: 40 | C23: 25 | D23: 15 | E23: 0.625 | F23: 7200 | G23: 🟡 Mixed signals
A24: March 2024 | B24: 40 | C24: 28 | D24: 12 | E24: 0.7 | F24: 14100 | G24: 🟢 Best month — Budget rally
A25: April 2024 | B25: 40 | C25: 24 | D25: 16 | E25: 0.6 | F25: 5800 | G25: 🟡 Consolidation
A26: May 2024 | B26: 40 | C26: 26 | D26: 14 | E26: 0.65 | F26: 9500 | G26: 🟢 Election momentum
A27: June 2024 | B27: 40 | C27: 22 | D27: 18 | E27: 0.55 | F27: 2100 | G27: 🔴 Post-election chop
A28: July 2024 | B28: 40 | C28: 27 | D28: 13 | E28: 0.675 | F28: 11200 | G28: 🟢 FII buying resumed
A29: August 2024 | B29: 40 | C29: 25 | D29: 15 | E29: 0.625 | F29: 7800 | G29: 🟡 Global cues mixed
A30: September 2024 | B30: 40 | C30: 24 | D30: 16 | E30: 0.6 | F30: 5200 | G30: 🟡 Quarterly expiry effect
A31: October 2024 | B31: 40 | C31: 26 | D31: 14 | E31: 0.65 | F31: 9800 | G31: 🟢 Festive season rally
A32: November 2024 | B32: 40 | C32: 21 | D32: 19 | E32: 0.525 | F32: -1400 | G32: 🔴 Worst — FII selling
A33: December 2024 | B33: 40 | C33: 27 | D33: 13 | E33: 0.675 | F33: 10300 | G33: 🟢 Year-end momentum
A35: 🏆 TOP 3 MONTHS | B35: March (+₹14,100), October (+₹9,800), January (+₹12,400)
A36: ⚠️ WORST 3 MONTHS | B36: Nov (FII selling), Jun (post-election chop), Apr (consolidation) — Reduce size in choppy months
A38: E. OPTIMIZATION REPORT — Best Settings for Nifty 50
A39: Parameter | B39: Recommended | C39: Rationale
A40: EMA Combination | B40: EMA 20 / 50 | C40: Best for intraday Nifty trend identification
A41: RSI Settings | B41: RSI 14, cross 50 | C41: Standard works well; RSI 9 for more signals
A42: Opening Range | B42: 15-minute ORH/ORL | C42: 30-min too slow for intraday; 15-min optimal
A43: Timeframe | B43: 15-min trend + 5-min trigger | C43: Dual timeframe reduces false signals by ~30%
A44: Volume Filter | B44: 1.5× 20-period avg | C44: Eliminates ~25% low-quality setups
A45: VIX Filter | B45: Trade only 12–20 VIX | C45: Avoids extreme volatility and dead markets

Sheet 📓 Weekly Review
A1: 📓 WEEKLY TRADE REVIEW — Fill every Friday
A3: WEEK 1 — Week of: _______________
A4: Trades Taken: | D4: Wins:
A5: Losses: | D5: Win Rate:
A6: Net P&L: | D6: Balance:
A7: What worked this week?
A10: What didn't work?
A13: Rule violations:
A16: Focus for next week:
A19: WEEK 2 — Week of: _______________
A20: Trades Taken: | D20: Wins:
A21: Losses: | D21: Win Rate:
A22: Net P&L: | D22: Balance:
A23: What worked this week?
A26: What didn't work?
A29: Rule violations:
A32: Focus for next week:
A35: WEEK 3 — Week of: _______________
A36: Trades Taken: | D36: Wins:
A37: Losses: | D37: Win Rate:
A38: Net P&L: | D38: Balance:
A39: What worked this week?
A42: What didn't work?
A45: Rule violations:
A48: Focus for next week:
A51: WEEK 4 — Week of: _______________
A52: Trades Taken: | D52: Wins:
A53: Losses: | D53: Win Rate:
A54: Net P&L: | D54: Balance:
A55: What worked this week?
A58: What didn't work?
A61: Rule violations:
A64: Focus for next week:
A67: WEEK 5 — Week of: _______________
A68: Trades Taken: | D68: Wins:
A69: Losses: | D69: Win Rate:
A70: Net P&L: | D70: Balance:
A71: What worked this week?
A74: What didn't work?
A77: Rule violations:
...

Sheet 🎯 Options Guide
A1: 🎯 OPTIONS CE/PE SYSTEM — Nifty 50 Intraday
A3: SIGNAL → OPTIONS TRANSLATION
A4: Signal | C4: Action | D4: Reason
A5: Nifty BUY signal | B5: → | C5: Buy ATM Call (CE) | D5: Bullish direction
A6: Nifty SELL signal | B6: → | C6: Buy ATM Put (PE) | D6: Bearish direction
A7: Ranging market | B7: → | C7: NO OPTIONS TRADE | D7: Capital protection
A10: STRIKE SELECTION FRAMEWORK
A11: Market Condition | B11: Strike Choice | C11: Premium Cost | D11: Why | E11: Risk Level
A12: Strong trend + momentum | B12: 1 OTM strike | C12: Lower cost | D12: Higher reward potential | E12: Medium
A13: Moderate signal | B13: ATM strike | C13: Standard | D13: Best Delta/cost balance | E13: Low
A14: Uncertain/weak signal | B14: SKIP — no trade | C14: ₹0 | D14: Capital protection | E14: None
A15: VIX > 20 | B15: ATM only | C15: Higher IV | D15: Avoid gamma risk of OTM | E15: Medium-High
A18: GREEKS CHEATSHEET — INTRADAY
A19: Greek | B19: Sweet Spot | C19: Summary | D19: Intraday Rule | E19: Status
A20: DELTA | B20: 0.4–0.6 (ATM range) | C20: Moves with Nifty | D20: Higher delta = more responsive | E20: 🟢 Favour
A21: THETA | B21: Decays every hour | C21: Your enemy! | D21: Exit before 2 PM — accelerates | E21: 🔴 Enemy
A22: VEGA | B22: Buy on low IV | C22: Expanding IV helps | D22: Avoid buying when IV already high | E22: 🟡 Monitor
A23: GAMMA | B23: Highest at ATM | C23: Accelerates near target | D23: Works in your favour near profit | E23: 🟢 Favour
A26: BEST DAYS FOR OPTIONS TRADING
A27: Day | B27: Rating | C27: Strategy Note
A28: Monday | B28: 🟢 GOOD | C28: Fresh weekly trend, good premium levels
A29: Tuesday | B29: 🟢 GOOD | C29: Continuation moves, high accuracy
A30: Wednesday | B30: 🟡 CAUTION | C30: Mid-week chop, trade with care
A31: Thursday | B31: 🟡 EXPIRY | C31: High theta decay — selling works better
A32: Friday | B32: 🔴 AVOID | C32: Pre-weekend — premium collapses

Sheet 🗺 90-Day Roadmap
A1: 🗺 90-DAY EXECUTION ROADMAP — Paper → Half-Size → Full Live
A3: DAYS 1–30 — PAPER TRADE ONLY
A4: ✅ | B4: Apply full strategy on paper — zero real money
A5: ✅ | B5: Fill trade tracker daily — every trade logged
A6: ✅ | B6: Target 65%+ win rate consistently before live | D6: Non-negotiable threshold
A7: ✅ | B7: Friday review — journal observations
A8: ✅ | B8: Study losing trades — identify pattern errors
A9: ✅ | B9: Goal: 30+ paper trades with 65% win rate | D9: Must achieve before Day 31
A11: DAYS 31–60 — LIVE TRADE — HALF SIZE
A12: ✅ | B12: Risk 1.5% per trade instead of full 3% | D12: Half size = half risk
A13: ✅ | B13: Max 2 trades per day — strict discipline
A14: ✅ | B14: Build real confidence with real money | D14: Psychology shifts with real P&L
A15: ✅ | B15: Continue weekly review every Friday
A16: ✅ | B16: If 2 losing weeks in a row → return to paper | D16: Drop back, rebuild confidence
A17: ✅ | B17: Goal: Profitable at half-size before full live
A19: DAYS 61–90 — FULL SYSTEM — LIVE
A20: ✅ | B20: Full 3% risk per trade — compounding active
A21: ✅ | B21: Add options CE/PE if paper was profitable | D21: Only if options paper was 65%+ WR
A22: ✅ | B22: Review monthly performance vs projections
A23: ✅ | B23: Scale capital when consistently profitable | D23: 2 profitable months minimum
A24: ✅ | B24: Never increase size after losses | D24: Size up only after winning streaks
A25: ✅ | B25: Goal: Self-sufficient, rules-based system | D25: Process > profit always
A27: 📊 MONTHLY INCOME PROJECTION (₹50K capital · 3% risk · 1:1.5 RR)
A28: Win Rate | B28: Trades/Day | C28: Days/Month | D28: Monthly P&L | E28: Annual P&L
A29: 0.55 | B29: 2 | C29: 20 | D29: 3200 | E29: 38400
A30: 0.65 | B30: 2 | C30: 20 | D30: 6800 | E30: 81600
A31: 0.7 | B31: 2 | C31: 20 | D31: 9500 | E31: 114000
A32: 0.75 | B32: 3 | C32: 20 | D32: 16200 | E32: 194400
